[2023-12-21 11:55:25,205] uvicorn.error - INFO - Started server process [984]
[2023-12-21 11:55:25,205] uvicorn.error - INFO - Waiting for application startup.
[2023-12-21 11:55:25,206] uvicorn.error - INFO - Application startup complete.
[2023-12-21 11:55:25,206] uvicorn.error - INFO - Uvicorn running on http://0.0.0.0:8080 (Press CTRL+C to quit)
[2023-12-21 11:56:02,028] root - INFO - Entered the load_object method of MainUtils class
[2023-12-21 11:56:02,046] root - INFO - Exited the load_object method of MainUtils class
[2023-12-21 11:56:02,047] uvicorn.error - ERROR - Exception in ASGI application
Traceback (most recent call last):
  File "main.py", line 78, in predict_route
    y_pred = model.predict(df)
NameError: name 'df' is not defined

During handling of the above exception, another exception occurred:

Traceback (most recent call last):
  File "/config/.local/lib/python3.8/site-packages/uvicorn/protocols/http/httptools_impl.py", line 404, in run_asgi
    result = await app(  # type: ignore[func-returns-value]
  File "/config/.local/lib/python3.8/site-packages/uvicorn/middleware/proxy_headers.py", line 78, in __call__
    return await self.app(scope, receive, send)
  File "/config/.local/lib/python3.8/site-packages/fastapi/applications.py", line 269, in __call__
    await super().__call__(scope, receive, send)
  File "/config/.local/lib/python3.8/site-packages/starlette/applications.py", line 124, in __call__
    await self.middleware_stack(scope, receive, send)
  File "/config/.local/lib/python3.8/site-packages/starlette/middleware/errors.py", line 184, in __call__
    raise exc
  File "/config/.local/lib/python3.8/site-packages/starlette/middleware/errors.py", line 162, in __call__
    await self.app(scope, receive, _send)
  File "/config/.local/lib/python3.8/site-packages/starlette/middleware/cors.py", line 84, in __call__
    await self.app(scope, receive, send)
  File "/config/.local/lib/python3.8/site-packages/starlette/exceptions.py", line 93, in __call__
    raise exc
  File "/config/.local/lib/python3.8/site-packages/starlette/exceptions.py", line 82, in __call__
    await self.app(scope, receive, sender)
  File "/config/.local/lib/python3.8/site-packages/fastapi/middleware/asyncexitstack.py", line 21, in __call__
    raise e
  File "/config/.local/lib/python3.8/site-packages/fastapi/middleware/asyncexitstack.py", line 18, in __call__
    await self.app(scope, receive, send)
  File "/config/.local/lib/python3.8/site-packages/starlette/routing.py", line 670, in __call__
    await route.handle(scope, receive, send)
  File "/config/.local/lib/python3.8/site-packages/starlette/routing.py", line 266, in handle
    await self.app(scope, receive, send)
  File "/config/.local/lib/python3.8/site-packages/starlette/routing.py", line 65, in app
    response = await func(request)
  File "/config/.local/lib/python3.8/site-packages/fastapi/routing.py", line 227, in app
    raw_response = await run_endpoint_function(
  File "/config/.local/lib/python3.8/site-packages/fastapi/routing.py", line 160, in run_endpoint_function
    return await dependant.call(**values)
  File "main.py", line 85, in predict_route
    raise Response(f"Error Occured! {e}")
TypeError: exceptions must derive from BaseException
[2023-12-21 11:56:02,927] root - INFO - Entered the load_object method of MainUtils class
[2023-12-21 11:56:02,933] root - INFO - Exited the load_object method of MainUtils class
[2023-12-21 11:56:02,934] uvicorn.error - ERROR - Exception in ASGI application
Traceback (most recent call last):
  File "main.py", line 78, in predict_route
    y_pred = model.predict(df)
NameError: name 'df' is not defined

During handling of the above exception, another exception occurred:

Traceback (most recent call last):
  File "/config/.local/lib/python3.8/site-packages/uvicorn/protocols/http/httptools_impl.py", line 404, in run_asgi
    result = await app(  # type: ignore[func-returns-value]
  File "/config/.local/lib/python3.8/site-packages/uvicorn/middleware/proxy_headers.py", line 78, in __call__
    return await self.app(scope, receive, send)
  File "/config/.local/lib/python3.8/site-packages/fastapi/applications.py", line 269, in __call__
    await super().__call__(scope, receive, send)
  File "/config/.local/lib/python3.8/site-packages/starlette/applications.py", line 124, in __call__
    await self.middleware_stack(scope, receive, send)
  File "/config/.local/lib/python3.8/site-packages/starlette/middleware/errors.py", line 184, in __call__
    raise exc
  File "/config/.local/lib/python3.8/site-packages/starlette/middleware/errors.py", line 162, in __call__
    await self.app(scope, receive, _send)
  File "/config/.local/lib/python3.8/site-packages/starlette/middleware/cors.py", line 84, in __call__
    await self.app(scope, receive, send)
  File "/config/.local/lib/python3.8/site-packages/starlette/exceptions.py", line 93, in __call__
    raise exc
  File "/config/.local/lib/python3.8/site-packages/starlette/exceptions.py", line 82, in __call__
    await self.app(scope, receive, sender)
  File "/config/.local/lib/python3.8/site-packages/fastapi/middleware/asyncexitstack.py", line 21, in __call__
    raise e
  File "/config/.local/lib/python3.8/site-packages/fastapi/middleware/asyncexitstack.py", line 18, in __call__
    await self.app(scope, receive, send)
  File "/config/.local/lib/python3.8/site-packages/starlette/routing.py", line 670, in __call__
    await route.handle(scope, receive, send)
  File "/config/.local/lib/python3.8/site-packages/starlette/routing.py", line 266, in handle
    await self.app(scope, receive, send)
  File "/config/.local/lib/python3.8/site-packages/starlette/routing.py", line 65, in app
    response = await func(request)
  File "/config/.local/lib/python3.8/site-packages/fastapi/routing.py", line 227, in app
    raw_response = await run_endpoint_function(
  File "/config/.local/lib/python3.8/site-packages/fastapi/routing.py", line 160, in run_endpoint_function
    return await dependant.call(**values)
  File "main.py", line 85, in predict_route
    raise Response(f"Error Occured! {e}")
TypeError: exceptions must derive from BaseException
[2023-12-21 12:00:46,235] uvicorn.error - INFO - Shutting down
[2023-12-21 12:00:46,336] uvicorn.error - INFO - Waiting for application shutdown.
[2023-12-21 12:00:46,336] uvicorn.error - INFO - Application shutdown complete.
[2023-12-21 12:00:46,336] uvicorn.error - INFO - Finished server process [984]
